<?xml version="1.0" encoding="utf-8"?>
<!-- This URDF was automatically created by SolidWorks to URDF Exporter! Originally created by Stephen Brawner (brawner@gmail.com) 
     Commit Version: 1.6.0-4-g7f85cfe  Build Version: 1.6.7995.38578
     For more information, please see http://wiki.ros.org/sw_urdf_exporter -->
<robot
  name="swmrob_v26">
  <link
    name="base_link">
    <inertial>
      <origin
        xyz="-0.00048529 0.00026068 0.017921"
        rpy="0 0 0" />
      <mass
        value="0.057426" />
      <inertia
        ixx="8.0665E-06"
        ixy="-4.7558E-08"
        ixz="-1.5248E-08"
        iyy="8.5295E-06"
        iyz="2.1229E-07"
        izz="1.0079E-05" />
    </inertial>
    <visual>
      <origin
        xyz="0 0 0"
        rpy="0 0 0" />
      <geometry>
        <mesh
          filename="package://swmrob_v26/meshes/base_link.STL" />
      </geometry>
      <material
        name="">
        <color
          rgba="1 0.76471 0.43529 1" />
      </material>
    </visual>
    <collision>
      <origin
        xyz="0 0 0"
        rpy="0 0 0" />
      <geometry>
        <mesh
          filename="package://swmrob_v26/meshes/base_link.STL" />
      </geometry>
    </collision>
  </link>
  <link
    name="headplate">
    <inertial>
      <origin
        xyz="-0.00011801 -0.0010291 0.0017348"
        rpy="0 0 0" />
      <mass
        value="0.012565" />
      <inertia
        ixx="7.8741E-06"
        ixy="7.508E-10"
        ixz="1.3285E-13"
        iyy="2.3568E-06"
        iyz="1.796E-17"
        izz="1.0202E-05" />
    </inertial>
    <visual>
      <origin
        xyz="0 0 0"
        rpy="0 0 0" />
      <geometry>
        <mesh
          filename="package://swmrob_v26/meshes/headplate.STL" />
      </geometry>
      <material
        name="">
        <color
          rgba="1 1 0.1451 1" />
      </material>
    </visual>
    <collision>
      <origin
        xyz="0 0 0"
        rpy="0 0 0" />
      <geometry>
        <mesh
          filename="package://swmrob_v26/meshes/headplate.STL" />
      </geometry>
    </collision>
  </link>
  <joint
    name="headplate"
    type="fixed">
    <origin
      xyz="0.00050422 -0.0026819 0.045605"
      rpy="0 0 0.054447" />
    <parent
      link="base_link" />
    <child
      link="headplate" />
    <axis
      xyz="0 0 0" />
  </joint>
  <link
    name="Left wheel">
    <inertial>
      <origin
        xyz="-0.0015204 1.3789E-13 -5.7954E-14"
        rpy="0 0 0" />
      <mass
        value="0.0025911" />
      <inertia
        ixx="5.2509E-07"
        ixy="-1.2119E-19"
        ixz="4.6405E-21"
        iyy="2.6486E-07"
        iyz="4.2466E-20"
        izz="2.6486E-07" />
    </inertial>
    <visual>
      <origin
        xyz="0 0 0"
        rpy="0 0 0" />
      <geometry>
        <mesh
          filename="package://swmrob_v26/meshes/Left wheel.STL" />
      </geometry>
      <material
        name="">
        <color
          rgba="1 1 1 1" />
      </material>
    </visual>
    <collision>
      <origin
        xyz="0 0 0"
        rpy="0 0 0" />
      <geometry>
        <mesh
          filename="package://swmrob_v26/meshes/Left wheel.STL" />
      </geometry>
    </collision>
  </link>
  <joint
    name="Left wheel"
    type="continuous">
    <origin
      xyz="0.029607 0.013227 0.01075"
      rpy="0.010581 0 0.010213" />
    <parent
      link="base_link" />
    <child
      link="Left wheel" />
    <axis
      xyz="1 0 0" />
  </joint>
  <link
    name="Right wheel">
    <inertial>
      <origin
        xyz="0.0015204 5.538E-05 -5.027E-05"
        rpy="0 0 0" />
      <mass
        value="0.0025911" />
      <inertia
        ixx="5.2509E-07"
        ixy="-5.5335E-20"
        ixz="-9.8203E-21"
        iyy="2.6486E-07"
        iyz="6.3344E-20"
        izz="2.6486E-07" />
    </inertial>
    <visual>
      <origin
        xyz="0 0 0"
        rpy="0 0 0" />
      <geometry>
        <mesh
          filename="package://swmrob_v26/meshes/Right wheel.STL" />
      </geometry>
      <material
        name="">
        <color
          rgba="1 1 1 1" />
      </material>
    </visual>
    <collision>
      <origin
        xyz="0 0 0"
        rpy="0 0 0" />
      <geometry>
        <mesh
          filename="package://swmrob_v26/meshes/Right wheel.STL" />
      </geometry>
    </collision>
  </link>
  <joint
    name="Right wheel"
    type="continuous">
    <origin
      xyz="-0.03039 0.012614 0.01075"
      rpy="0.0021341 0 0.010213" />
    <parent
      link="base_link" />
    <child
      link="Right wheel" />
    <axis
      xyz="1 0 0" />
  </joint>
</robot>